Workbook

Sheet README
A1: BESS hazardous scenarios – source workbook for the HTML page
A2: This workbook is the single source for the HTML. Edit it, then upload it and ask Claude to rebuild the HTML (or run build_html.py yourself: python build_html.py this_file.xlsx).
A4: Rules
A5: • Do not rename sheets or header cells (row 1). Add rows at the bottom of a table; delete a row to remove an item. Column order may not change.
A6: • Cells with several items: put ONE ITEM PER LINE inside the cell (Alt+Enter in Excel). Used in: Sequence steps, Consequences, Hazards, Hazard types.
A7: • SF IDs in Scenarios: comma-separated, e.g. SF-01, SF-11. The 'Covers' list of each safety function is built automatically from this column – do not maintain it twice.
A8: • Component, Group, Primary hazard type and Hazard types must match a name in the Lists sheet (dropdowns help). A new component needs a row in Lists with a colour.
A9: • Final element tags (Safety functions): semicolon-separated short names. They drive the 'Shared elements' bars. Use the same spelling for the same device.
A10: • Page text: plain text. Write a scenario ID in square brackets, e.g. [OC-03], to turn it into a clickable link.
A11: • Grey columns are formulas (checks only). They are ignored by the HTML builder.
A13: Sheets
A14: Scenarios – one row per initiating event (IE = technical condition + mechanism → sequence → consequences → hazard).
... A19: Checks – counts and reference checks.

Sheet Scenarios
A1: ID | B1: Group | C1: Component (IE owner) | D1: Operating mode / phase | E1: Initiating event (summary) | F1: IE – Technical condition | G1: IE – Mechanism | H1: Sequence steps (one per line) | I1: Consequences (one per line) | J1: Hazards – person harmed (one per line) | K1: Exposed persons | L1: Primary hazard type | M1: Hazard types (one per line) | N1: Early signal / detectable deviation | O1: SF IDs (comma-separated) | P1: Check: unknown SF IDs
A2: OV-01 | B2: Overcharge / Overvoltage | C2: PCS | D2: Normal operation (charging) | E2: PCS fails to follow BMS charge limit / stop request | F2: PCS charge controller (current/voltage loop) failed – BMS limits and stop request are correct | G2: PCS control or firmware fault ignores the BMS charge limit / stop request and keeps charging (setpoint stuck) | H2: BMS requests stop PCS keeps charging cell overvoltage Li plating / cathode decomposition cell self-heating TR | I2: Cell thermal runaway (TR) → propagation to adjacent cells/modules flammable + toxic vent gas (H2, CO, HF, VOC) release module/rack fire possible deflagration in enclosure fire spread to adjacent containers/PCS | J2: Technician/firefighter at or near the container is exposed to fire, jet flame and radiant heat → burns. Person opening or standing at the enclosure door is exposed to deflagration overpressure, fireball and projectiles (door, panels). Personnel/public downwind inhale toxic combustion gases (HF, CO, HCN) → poisoning. | K2: O&M technicians, firefighters, public near site fence / downwind | L2: Fire | M2: Fire Explosion Toxic | N2: Cell V > Vmax; SOC > 100 %; charge current still flowing at EoC; cell temp rise; off-gas | O2: SF-01, SF-11 | P2: =IF(O2="","none",IF(SUMPRODUCT(ISNUMBER(SEARCH('Safety functions'!$A$2:$A$200,O2))*('Safety functions'!$A$2:$A$200<>""))=LEN(O2)-LEN(SUBSTITUTE(O2,",",""))+1,"OK","check")) -> OK
A3: OV-02 | B3: Overcharge / Overvoltage | C3: BMS–PCS comm link | D3: Normal operation (charging) | E3: Loss of BMS–PCS communication with PCS continuing last charge setpoint | F3: Loss of BMS–PCS communication (CAN/Modbus/Ethernet link down) | G3: Link down; PCS has no comm-loss watchdog and keeps running at last received charge setpoint | H3: No charge-limit updates reach PCS charging continues past limits cell overvoltage TR | I3: Cell thermal runaway (TR) → propagation to adjacent cells/modules flammable + toxic vent gas (H2, CO, HF, VOC) release module/rack fire possible deflagration in enclosure fire spread to adjacent containers/PCS | J3: Technician/firefighter at or near the container is exposed to fire, jet flame and radiant heat → burns. Person opening or standing at the enclosure door is exposed to deflagration overpressure, fireball and projectiles (door, panels). Personnel/public downwind inhale toxic combustion gases (HF, CO, HCN) → poisoning. | K3: O&M technicians, firefighters, public near site fence / downwind | L3: Fire | M3: Fire Explosion Toxic | N3: Comm heartbeat lost; cell V rising; SOC > limit | O3: SF-01, SF-02, SF-11 | P3: =IF(O3="","none",IF(SUMPRODUCT(ISNUMBER(SEARCH('Safety functions'!$A$2:$A$200,O3))*('Safety functions'!$A$2:$A$200<>""))=LEN(O3)-LEN(SUBSTITUTE(O3,",",""))+1,"OK","check")) -> OK
A4: OV-03 | B4: Overcharge / Overvoltage | C4: BMS | D4: Normal operation (charging) | E4: BMS cell-voltage sensing error causes undetected overcharge | F4: BMS cell-voltage measurement drifts low (AFE / ADC reference drift, wiring resistance) | G4: BMS believes cells are below limit and permits charging while actual cell voltage exceeds Vmax | H4: Measured V < actual V BMS does not request stop real cell overvoltage TR | I4: Cell thermal runaway (TR) → propagation to adjacent cells/modules flammable + toxic vent gas (H2, CO, HF, VOC) release module/rack fire possible deflagration in enclosure fire spread to adjacent containers/PCS | J4: Technician/firefighter at or near the container is exposed to fire, jet flame and radiant heat → burns. Person opening or standing at the enclosure door is exposed to deflagration overpressure, fireball and projectiles (door, panels). Personnel/public downwind inhale toxic combustion gases (HF, CO, HCN) → poisoning. | K4: O&M technicians, firefighters, public near site fence / downwind | L4: Fire | M4: Fire Explosion Toxic | N4: Discrepancy between cell-sum and string voltage; redundant measurement mismatch | O4: SF-01, SF-11 | P4: =IF(O4="","none",IF(SUMPRODUCT(ISNUMBER(SEARCH('Safety functions'!$A$2:$A$200,O4))*('Safety functions'!$A$2:$A$200<>""))=LEN(O4)-LEN(SUBSTITUTE(O4,",",""))+1,"OK","check")) -> OK
A5: OV-04 | B5: Overcharge / Overvoltage | C5: BMS | D5: Normal operation (charging) | E5: Single-cell overcharge due to imbalance / balancing failure | F5: Cell imbalance: weak/low-capacity cell or failed balancing circuit | G5: String-level voltage looks normal while one cell is driven above Vmax | H5: Weak cell reaches full charge first continues to be charged with string local overvoltage TR of that cell propagation | I5: Cell thermal runaway (TR) → propagation to adjacent cells/modules flammable + toxic vent gas (H2, CO, HF, VOC) release module/rack fire possible deflagration in enclosure fire spread to adjacent containers/PCS | J5: Technician/firefighter at or near the container is exposed to fire, jet flame and radiant heat → burns. Person opening or standing at the enclosure door is exposed to deflagration overpressure, fireball and projectiles (door, panels). Personnel/public downwind inhale toxic combustion gases (HF, CO, HCN) → poisoning. | K5: O&M technicians, firefighters, public near site fence / downwind | L5: Fire | M5: Fire Explosion Toxic | N5: Max-min cell voltage spread increasing; single cell V > Vmax | O5: SF-01, SF-11 | P5: =IF(O5="","none",IF(SUMPRODUCT(ISNUMBER(SEARCH('Safety functions'!$A$2:$A$200,O5))*('Safety functions'!$A$2:$A$200<>""))=LEN(O5)-LEN(SUBSTITUTE(O5,",",""))+1,"OK","check")) -> OK
A6: OV-05 | B6: Overcharge / Overvoltage | C6: BMS | D6: Normal operation (charging) | E6: SOC estimation error leads to charging beyond true capacity | F6: SOC estimation error (coulomb-counting drift, wrong OCV table, SOH not updated) | G6: EMS dispatches charge based on false SOC; cells charged beyond true 100 % SOC | H6: EMS charge command continues actual SOC > 100 % overvoltage TR | I6: Cell thermal runaway (TR) → propagation to adjacent cells/modules flammable + toxic vent gas (H2, CO, HF, VOC) release module/rack fire possible deflagration in enclosure fire spread to adjacent containers/PCS | J6: Technician/firefighter at or near the container is exposed to fire, jet flame and radiant heat → burns. Person opening or standing at the enclosure door is exposed to deflagration overpressure, fireball and projectiles (door, panels). Personnel/public downwind inhale toxic combustion gases (HF, CO, HCN) → poisoning. | K6: O&M technicians, firefighters, public near site fence / downwind | L6: Fire | M6: Fire Explosion Toxic | N6: Cell V vs SOC mismatch; V at top limit while SOC < 100 % | O6: SF-01, SF-11 | P6: =IF(O6="","none",IF(SUMPRODUCT(ISNUMBER(SEARCH('Safety functions'!$A$2:$A$200,O6))*('Safety functions'!$A$2:$A$200<>""))=LEN(O6)-LEN(SUBSTITUTE(O6,",",""))+1,"OK","check")) -> OK
A7: OV-06 | B7: Overcharge / Overvoltage | C7: BMS | D7: Normal operation (charging) | E7: BMS sends wrong charge limit / no stop request | F7: BMS charge-limit logic failed (software/logic error) – PCS itself works correctly | G7: BMS sends wrong charge limits (CCL/CVL too high) or never sends the end-of-charge request; PCS follows the wrong command | H7: PCS follows BMS command charging continues past limit cell overvoltage TR | I7: Cell thermal runaway (TR) → propagation to adjacent cells/modules flammable + toxic vent gas (H2, CO, HF, VOC) release module/rack fire possible deflagration in enclosure fire spread to adjacent containers/PCS | J7: Technician/firefighter at or near the container is exposed to fire, jet flame and radiant heat → burns. Person opening or standing at the enclosure door is exposed to deflagration overpressure, fireball and projectiles (door, panels). Personnel/public downwind inhale toxic combustion gases (HF, CO, HCN) → poisoning. | K7: O&M technicians, firefighters, public near site fence / downwind | L7: Fire | M7: Fire Explosion Toxic | N7: Cell V > Vmax while BMS CCL > 0; CVL above cell rating | O7: SF-01, SF-11 | P7: =IF(O7="","none",IF(SUMPRODUCT(ISNUMBER(SEARCH('Safety functions'!$A$2:$A$200,O7))*('Safety functions'!$A$2:$A$200<>""))=LEN(O7)-LEN(SUBSTITUTE(O7,",",""))+1,"OK","check")) -> OK
A8: OD-01 | B8: Overdischarge / Low-temperature charging | C8: BMS | D8: Idle / long standby, then recharge | E8: Overdischarge followed by recharge of damaged cells | F8: Cells driven below minimum voltage (UV cutoff failed, or parasitic BMS/aux load during long idle) | G8: Copper current collector dissolves; on subsequent recharge Cu redeposits as dendrites | H8: Cell V < Vmin Cu dissolution recharge Cu dendrites pierce separator internal short TR | I8: Cell thermal runaway (TR) → propagation to adjacent cells/modules flammable + toxic vent gas (H2, CO, HF, VOC) release module/rack fire possible deflagration in enclosure fire spread to adjacent containers/PCS | J8: Technician/firefighter at or near the container is exposed to fire, jet flame and radiant heat → burns. Person opening or standing at the enclosure door is exposed to deflagration overpressure, fireball and projectiles (door, panels). Personnel/public downwind inhale toxic combustion gases (HF, CO, HCN) → poisoning. | K8: O&M technicians, firefighters, public near site fence / downwind | L8: Fire | M8: Fire Explosion Toxic | N8: Cell V < Vmin (history); abnormal self-discharge | O8: SF-04 | P8: =IF(O8="","none",IF(SUMPRODUCT(ISNUMBER(SEARCH('Safety functions'!$A$2:$A$200,O8))*('Safety functions'!$A$2:$A$200<>""))=LEN(O8)-LEN(SUBSTITUTE(O8,",",""))+1,"OK","check")) -> OK
A9: OD-02 | B9: Overdischarge / Low-temperature charging | C9: Thermal management (HVAC) | D9: Normal operation (charging) in cold climate | E9: Charging at low cell temperature | F9: Enclosure/battery heater failed in cold climate (HVAC heating function) | G9: Cells stay below charge-temperature limit and are charged anyway → lithium plating on anode | H9: Li plating dendrite growth internal short (possibly delayed) TR | I9: Cell thermal runaway (TR) → propagation to adjacent cells/modules flammable + toxic vent gas (H2, CO, HF, VOC) release module/rack fire possible deflagration in enclosure fire spread to adjacent containers/PCS | J9: Technician/firefighter at or near the container is exposed to fire, jet flame and radiant heat → burns. Person opening or standing at the enclosure door is exposed to deflagration overpressure, fireball and projectiles (door, panels). Personnel/public downwind inhale toxic combustion gases (HF, CO, HCN) → poisoning. | K9: O&M technicians, firefighters, public near site fence / downwind | L9: Fire | M9: Fire Explosion Toxic | N9: Cell T < Tmin_charge while I_charge > 0 | O9: SF-05 | P9: =IF(O9="","none",IF(SUMPRODUCT(ISNUMBER(SEARCH('Safety functions'!$A$2:$A$200,O9))*('Safety functions'!$A$2:$A$200<>""))=LEN(O9)-LEN(SUBSTITUTE(O9,",",""))+1,"OK","check")) -> OK
A10: OC-01 | B10: Overcurrent / Short circuit | C10: PCS | D10: Normal operation | E10: PCS overcurrent due to current-control failure | F10: PCS current control failure (sensor fault, control loop instability) | G10: Charge/discharge current above cell/busbar rating | H10: Excess current Joule heating in cells, busbars, cables cell overtemperature / insulation melting TR or cable fire | I10: Cell overheating / TR busbar or DC cable overheating and insulation fire arc | J10: Personnel near container/PCS exposed to fire and radiant heat → burns. Personnel inhale toxic smoke from cable/cell fire. | K10: O&M technicians, firefighters | L10: Fire | M10: Fire Toxic | N10: Rack current > Imax; busbar/cable temperature | O10: SF-06 | P10: =IF(O10="","none",IF(SUMPRODUCT(ISNUMBER(SEARCH('Safety functions'!$A$2:$A$200,O10))*('Safety functions'!$A$2:$A$200<>""))=LEN(O10)-LEN(SUBSTITUTE(O10,",",""))+1,"OK","check")) -> OK
A11: OC-02 | B11: Overcurrent / Short circuit | C11: DC electrical | D11: Normal operation / maintenance | E11: External DC short circuit | F11: Insulation breakdown between DC+ and DC– (damaged cable, degraded busbar insulation, conductive debris, dropped tool) | G11: Bolted/arcing external short circuit fed by battery (tens of kA) | H11: Very high fault current DC arc, busbar melting, cell heating fire; possible TR | I11: DC arc flash molten metal ejection rack fire possible TR loss of DC isolation | J11: Technician near the rack/combiner is exposed to DC arc flash (thermal burns, eye injury, blast). Personnel exposed to subsequent fire. | K11: O&M technicians | L11: Arc flash | M11: Arc flash Fire | N11: DC fault current; rapid voltage collapse; arc fault detection | O11: SF-06, SF-07 | P11: =IF(O11="","none",IF(SUMPRODUCT(ISNUMBER(SEARCH('Safety functions'!$A$2:$A$200,O11))*('Safety functions'!$A$2:$A$200<>""))=LEN(O11)-LEN(SUBSTITUTE(O11,",",""))+1,"OK","check")) -> OK
A12: OC-03 | B12: Overcurrent / Short circuit | C12: DC electrical | D12: Start-up / energization | E12: Pre-charge failure causes contactor welding | F12: Pre-charge circuit failed (resistor open, pre-charge bypassed) | G12: Main contactor closes onto discharged PCS DC-link capacitors → large inrush → contacts weld | H12: Inrush current contactor contacts weld contactor shows 'open' command but stays closed DC side remains energized / isolation lost | I12: Welded contactor (loss of isolation / loss of trip function) DC-link capacitor damage arc | J12: Technician trusts the 'isolated' status and works on DC side that is still live → electric shock / arc flash. | K12: O&M technicians | L12: Electric shock | M12: Electric shock Arc flash | N12: Contactor auxiliary contact vs voltage mismatch; inrush current | O12: SF-08, SF-19 | P12: =IF(O12="","none",IF(SUMPRODUCT(ISNUMBER(SEARCH('Safety functions'!$A$2:$A$200,O12))*('Safety functions'!$A$2:$A$200<>""))=LEN(O12)-LEN(SUBSTITUTE(O12,",",""))+1,"OK","check")) -> OK
A13: OC-04 | B13: Overcurrent / Short circuit | C13: DC electrical | D13: Normal operation | E13: Loose / high-resistance electrical connection | F13: High-resistance joint (bolt torque loss from thermal cycling/vibration, corrosion) | G13: Local Joule heating at the joint → hotspot | H13: Hotspot insulation melting / arcing adjacent cell heating TR or rack fire | I13: Local fire at joint arc cell TR of nearby cells | J13: Technician/firefighter at or near the container is exposed to fire, jet flame and radiant heat → burns. Person opening or standing at the enclosure door is exposed to deflagration overpressure, fireball and projectiles (door, panels). Personnel/public downwind inhale toxic combustion gases (HF, CO, HCN) → poisoning. | K13: O&M technicians, firefighters, public near site fence / downwind | L13: Fire | M13: Fire Arc flash Toxic | N13: Joint temperature; voltage drop across connection; IR thermography | O13: SF-07, SF-09 | P13: =IF(O13="","none",IF(SUMPRODUCT(ISNUMBER(SEARCH('Safety functions'!$A$2:$A$200,O13))*('Safety functions'!$A$2:$A$200<>""))=LEN(O13)-LEN(SUBSTITUTE(O13,",",""))+1,"OK","check")) -> OK
... A21: ME-02 | B21: Mechanical / External damage | C21: External / site | D21: Any | E21: Earthquake causes rack collapse | F21: Seismic event (earthquake) exceeding rack/anchor design | G21: Rack toppling / module drop, cable pull-out | H21: Module/cell damage + cable short arc fire / TR | I21: Rack collapse short circuit arc fire TR | J21: Person inside walk-in enclosure crushed by falling rack/modules. Personnel exposed to fire/arc/toxic gas afterward. | K21: O&M technicians, firefighters | L21: Mechanical | M21: Mechanical Fire Arc flash Toxic | N21: Seismic sensor; multiple rack faults | O21: SF-14 | P21: =IF(O21="","none",IF(SUMPRODUCT(ISNUMBER(SEARCH('Safety functions'!$A$2:$A$200,O21))*('Safety functions'!$A$2:$A$200<>""))=LEN(O21)-LEN(SUBSTITUTE(O21,",",""))+1,"OK","check")) -> OK
A22: ME-03 | B22: Mechanical / External damage | C22: People & lifecycle | D22: Installation / module replacement | E22: Module dropped during handling | F22: Lifting equipment or handling failure | G22: Heavy module drops | H22: Drop crush injury; internal cell damage delayed TR | I22: Crush injury damaged cells delayed TR | J22: Worker under/near load crushed. Personnel later exposed to fire from damaged module. | K22: Installers, O&M technicians | L22: Mechanical | M22: Mechanical Fire | N22: — | P22: =IF(O22="","none",IF(SUMPRODUCT(ISNUMBER(SEARCH('Safety functions'!$A$2:$A$200,O22))*('Safety functions'!$A$2:$A$200<>""))=LEN(O22)-LEN(SUBSTITUTE(O22,",",""))+1,"OK","check")) -> none
A23: EX-01 | B23: External fire / Environment | C23: External / site | D23: Any | E23: External fire exposure | F23: External fire (wildfire, vegetation, adjacent container, transformer fire) | G23: Radiant/convective heat into enclosure → cell heating | H23: External heat cell T rise TR fire spread into and between units | I23: Cell thermal runaway (TR) → propagation to adjacent cells/modules flammable + toxic vent gas (H2, CO, HF, VOC) release module/rack fire possible deflagration in enclosure fire spread to adjacent containers/PCS | J23: Technician/firefighter at or near the container is exposed to fire, jet flame and radiant heat → burns. Person opening or standing at the enclosure door is exposed to deflagration overpressure, fireball and projectiles (door, panels). Personnel/public downwind inhale toxic combustion gases (HF, CO, HCN) → poisoning. | K23: O&M technicians, firefighters, public near site fence / downwind, neighbours | L23: Fire | M23: Fire Explosion Toxic | N23: Enclosure external/internal temperature; flame detection | O23: SF-16 | P23: =IF(O23="","none",IF(SUMPRODUCT(ISNUMBER(SEARCH('Safety functions'!$A$2:$A$200,O23))*('Safety functions'!$A$2:$A$200<>""))=LEN(O23)-LEN(SUBSTITUTE(O23,",",""))+1,"OK","check")) -> OK
A24: EX-02 | B24: External fire / Environment | C24: External / site | D24: Storm / flooding | E24: Flooding of BESS enclosure | F24: Flood or storm-water ingress (drainage failure, low-lying site) | G24: Modules/busbars submerged; short circuit; electrolysis | H24: Water ingress shorts arc/fire; electrolysis H2 generation (esp. saline water) explosive atmosphere | I24: Short circuit fire H2 accumulation / explosion energized water | J24: Person wading near flooded, energized equipment → electric shock. Personnel exposed to fire/H2 explosion. | K24: O&M technicians, firefighters, public | L24: Electric shock | M24: Electric shock Fire Explosion | N24: Water level sensor; insulation resistance drop | O24: SF-12, SF-15, SF-17 | P24: =IF(O24="","none",IF(SUMPRODUCT(ISNUMBER(SEARCH('Safety functions'!$A$2:$A$200,O24))*('Safety functions'!$A$2:$A$200<>""))=LEN(O24)-LEN(SUBSTITUTE(O24,",",""))+1,"OK","check")) -> OK
A25: EX-03 | B25: External fire / Environment | C25: External / site | D25: Thunderstorm | E25: Lightning / surge overvoltage | F25: Lightning strike or switching surge | G25: Overvoltage on DC/AC → insulation breakdown; ground potential rise | H25: Insulation breakdown arc fire; high step/touch voltage around earthing | I25: Equipment insulation failure arc fire ground potential rise | J25: Person on site during strike exposed to step/touch voltage → shock. Personnel exposed to resulting fire. | K25: O&M technicians, public at fence | L25: Electric shock | M25: Electric shock Fire | N25: Surge counter; insulation monitoring | P25: =IF(O25="","none",IF(SUMPRODUCT(ISNUMBER(SEARCH('Safety functions'!$A$2:$A$200,O25))*('Safety functions'!$A$2:$A$200<>""))=LEN(O25)-LEN(SUBSTITUTE(O25,",",""))+1,"OK","check")) -> none
A26: EX-04 | B26: External fire / Environment | C26: External / site | D26: Normal operation | E26: Condensation inside enclosure | F26: Condensation / high humidity (dehumidification failure, cold surfaces) | G26: Moisture on PCBs/busbars → tracking, BMS malfunction | H26: Tracking arc fire; BMS measurement faults loss of protection | I26: Arc fire BMS malfunction ground fault | J26: Personnel exposed to fire/arc → burns; toxic smoke. | K26: O&M technicians | L26: Fire | M26: Fire Arc flash | N26: Humidity; dew point; insulation resistance | O26: SF-17 | P26: =IF(O26="","none",IF(SUMPRODUCT(ISNUMBER(SEARCH('Safety functions'!$A$2:$A$200,O26))*('Safety functions'!$A$2:$A$200<>""))=LEN(O26)-LEN(SUBSTITUTE(O26,",",""))+1,"OK","check")) -> OK
A27: EX-05 | B27: External fire / Environment | C27: External / site | D27: Normal operation | E27: Animal or debris ingress causes insulation damage | F27: Rodent / insect / dust ingress | G27: Insulation chewed or conductive bridging | H27: Insulation damage short arc fire | I27: Arc fire ground fault | J27: Personnel exposed to fire/arc → burns. | K27: O&M technicians | L27: Fire | M27: Fire Arc flash | N27: Insulation resistance; ground-fault alarm | O27: SF-17 | P27: =IF(O27="","none",IF(SUMPRODUCT(ISNUMBER(SEARCH('Safety functions'!$A$2:$A$200,O27))*('Safety functions'!$A$2:$A$200<>""))=LEN(O27)-LEN(SUBSTITUTE(O27,",",""))+1,"OK","check")) -> OK
A28: GX-01 | B28: Gas release / Explosion / Toxic | C28: Battery cell | D28: Any (often discovered during response) | E28: Cell venting into poorly ventilated enclosure | F28: Cell off-gassing without ignition (e.g. internal short) in a closed enclosure | G28: Flammable gas accumulates above LFL because exhaust ventilation is off/failed or not triggered | H28: Vent gas (H2, CO, hydrocarbons) accumulates ignition source (arc, hot cell, door opened admitting air) deflagration | I28: Explosive atmosphere deflagration enclosure rupture follow-on fire | J28: Firefighter/technician opening the door or standing in front of the enclosure is hit by deflagration overpressure, fireball and flying door/panels (cf. McMicken 2019). | K28: Firefighters, O&M technicians | L28: Explosion | M28: Explosion Fire Toxic | N28: Gas concentration (H2 / CO / VOC) % LFL | O28: SF-12 | P28: =IF(O28="","none",IF(SUMPRODUCT(ISNUMBER(SEARCH('Safety functions'!$A$2:$A$200,O28))*('Safety functions'!$A$2:$A$200<>""))=LEN(O28)-LEN(SUBSTITUTE(O28,",",""))+1,"OK","check")) -> OK
A29: GX-02 | B29: Gas release / Explosion / Toxic | C29: Battery cell | D29: Inspection / maintenance | E29: Electrolyte leak from damaged cell | F29: Cell casing breach (swollen/damaged cell, seal failure) | G29: Liquid electrolyte leaks; reacts with moisture forming HF; flammable vapour | H29: Leak flammable/corrosive vapour in module exposure on opening module; possible ignition | I29: Flammable vapour HF formation chemical contamination possible fire | J29: Technician opening the module inhales HF / electrolyte vapour or gets skin/eye contact → chemical burns, poisoning. | K29: O&M technicians | L29: Toxic | M29: Toxic Chemical burn Fire | N29: Electrolyte vapour / VOC detection; visual swelling | O29: SF-11 | P29: =IF(O29="","none",IF(SUMPRODUCT(ISNUMBER(SEARCH('Safety functions'!$A$2:$A$200,O29))*('Safety functions'!$A$2:$A$200<>""))=LEN(O29)-LEN(SUBSTITUTE(O29,",",""))+1,"OK","check")) -> OK
A30: GX-03 | B30: Gas release / Explosion / Toxic | C30: Thermal management (HVAC) | D30: Any | E30: HVAC refrigerant leak into occupied enclosure | F30: Refrigerant leak inside enclosure (A1 high concentration, or flammable A2L/A3 refrigerant) | G30: Refrigerant displaces oxygen or forms flammable mixture | H30: Leak O2 depletion or flammable atmosphere asphyxiation / ignition | I30: Oxygen-deficient atmosphere flammable mixture fire | J30: Technician entering walk-in enclosure is asphyxiated or exposed to flash fire. | K30: O&M technicians | L30: Asphyxiation | M30: Asphyxiation Fire | N30: Refrigerant / O2 detector | O30: SF-29 | P30: =IF(O30="","none",IF(SUMPRODUCT(ISNUMBER(SEARCH('Safety functions'!$A$2:$A$200,O30))*('Safety functions'!$A$2:$A$200<>""))=LEN(O30)-LEN(SUBSTITUTE(O30,",",""))+1,"OK","check")) -> OK
A31: SH-01 | B31: Electric shock / Arc flash (DC) | C31: DC electrical | D31: Normal operation / maintenance | E31: Undetected first DC ground fault | F31: DC insulation fault to earth (cable abrasion, moisture) not detected (IMD failed or alarm ignored) | G31: First fault makes one pole earth-referenced; second fault → short circuit | H31: Pole at earth potential touching other pole = full DC voltage; second fault high-current short arc/fire | I31: Hidden touch-voltage hazard double ground fault short arc fire | J31: Technician touching a 'safe' DC conductor while standing on earth receives up to 1500 VDC shock. Personnel exposed to arc/fire from second fault. | K31: O&M technicians | L31: Electric shock | M31: Electric shock Arc flash Fire | N31: Insulation resistance (IMD) value | O31: SF-17 | P31: =IF(O31="","none",IF(SUMPRODUCT(ISNUMBER(SEARCH('Safety functions'!$A$2:$A$200,O31))*('Safety functions'!$A$2:$A$200<>""))=LEN(O31)-LEN(SUBSTITUTE(O31,",",""))+1,"OK","check")) -> OK
A32: SH-02 | B32: Electric shock / Arc flash (DC) | C32: People & lifecycle | D32: Maintenance | E32: Maintenance on rack that cannot be fully de-energized | F32: Stranded energy: series-connected modules are always energized even with contactors open | G32: Work on 'isolated' rack, contact across module links or tool drop across terminals | H32: Contact with live inter-module busbar shock; tool bridging short arc | I32: Electric shock DC arc flash module damage | J32: Technician working on the rack contacts live inter-module conductors → electric shock / arc flash burns. | K32: O&M technicians | L32: Electric shock | M32: Electric shock Arc flash | N32: — | P32: =IF(O32="","none",IF(SUMPRODUCT(ISNUMBER(SEARCH('Safety functions'!$A$2:$A$200,O32))*('Safety functions'!$A$2:$A$200<>""))=LEN(O32)-LEN(SUBSTITUTE(O32,",",""))+1,"OK","check")) -> none
A33: SH-03 | B33: Electric shock / Arc flash (DC) | C33: PCS | D33: Maintenance | E33: Residual energy in PCS DC-link after isolation | F33: DC-link capacitor discharge resistor failed | G33: Capacitors remain charged after isolation | H33: Technician opens PCS assuming de-energized contacts charged capacitor | I33: Stored-energy discharge shock arc | J33: Technician touches charged DC-link bus → electric shock / burns. | K33: O&M technicians | L33: Electric shock | M33: Electric shock Arc flash | N33: DC-link voltage indication | O33: SF-19 | P33: =IF(O33="","none",IF(SUMPRODUCT(ISNUMBER(SEARCH('Safety functions'!$A$2:$A$200,O33))*('Safety functions'!$A$2:$A$200<>""))=LEN(O33)-LEN(SUBSTITUTE(O33,",",""))+1,"OK","check")) -> OK
A34: SH-04 | B34: Electric shock / Arc flash (DC) | C34: People & lifecycle | D34: Maintenance / measurement | E34: Short circuit during live DC work | F34: Live work on DC equipment (measurement, fuse replacement) | G34: Probe slip / tool drop / wrong test equipment causes short | H34: Arc initiation DC arc does not self-extinguish arc flash | I34: DC arc flash molten metal blast | J34: Technician performing the work is exposed to arc flash → burns, eye injury. | K34: O&M technicians | L34: Arc flash | M34: Arc flash | N34: — | P34: =IF(O34="","none",IF(SUMPRODUCT(ISNUMBER(SEARCH('Safety functions'!$A$2:$A$200,O34))*('Safety functions'!$A$2:$A$200<>""))=LEN(O34)-LEN(SUBSTITUTE(O34,",",""))+1,"OK","check")) -> none
A35: SH-05 | B35: Electric shock / Arc flash (DC) | C35: External / site | D35: Any | E35: Loss of protective earth connection | F35: Loss of protective earth (corrosion, loose joint, copper theft) combined with insulation fault | G35: Enclosure / fence becomes energized | H35: Insulation fault energizes exposed conductive part with no fault path no protection trip | I35: Energized enclosure / fence touch voltage | J35: Worker or member of public touching the enclosure/fence receives electric shock. | K35: O&M technicians, public | L35: Electric shock | M35: Electric shock | N35: Earth continuity monitoring; touch-voltage measurement | O35: SF-18 | P35: =IF(O35="","none",IF(SUMPRODUCT(ISNUMBER(SEARCH('Safety functions'!$A$2:$A$200,O35))*('Safety functions'!$A$2:$A$200<>""))=LEN(O35)-LEN(SUBSTITUTE(O35,",",""))+1,"OK","check")) -> OK
A36: SH-06 | B36: Electric shock / Arc flash (DC) | C36: External / site | D36: Any | E36: Unauthorized entry into energized BESS area | F36: Unauthorized access (intruder, copper theft, vandalism) | G36: Contact with live parts or damage to equipment | H36: Contact with live conductors; cable cutting short arc/fire | I36: Electric shock arc fire | J36: Intruder contacts live parts → electrocution / burns; later fire endangers responders. | K36: Public / intruders, firefighters | L36: Electric shock | M36: Electric shock Arc flash Fire | N36: Door switch / intrusion alarm | O36: SF-33 | P36: =IF(O36="","none",IF(SUMPRODUCT(ISNUMBER(SEARCH('Safety functions'!$A$2:$A$200,O36))*('Safety functions'!$A$2:$A$200<>""))=LEN(O36)-LEN(SUBSTITUTE(O36,",",""))+1,"OK","check")) -> OK
A37: GR-01 | B37: Grid interface / AC side | C37: PCS | D37: Grid outage | E37: Anti-islanding failure during grid outage | F37: Grid outage / upstream breaker opens | G37: PCS fails to detect island (detection failure, wrong settings) and continues to energize the disconnected section | H37: BESS keeps islanded feeder energized line assumed dead | I37: Unintentional island energized 'dead' line out-of-phase reclosing risk | J37: Utility line worker contacts line believed de-energized → electrocution. | K37: Utility line workers | L37: Electric shock | M37: Electric shock | N37: Loss of grid (V/f/ROCOF/vector shift) | O37: SF-20 | P37: =IF(O37="","none",IF(SUMPRODUCT(ISNUMBER(SEARCH('Safety functions'!$A$2:$A$200,O37))*('Safety functions'!$A$2:$A$200<>""))=LEN(O37)-LEN(SUBSTITUTE(O37,",",""))+1,"OK","check")) -> OK
A38: GR-02 | B38: Grid interface / AC side | C38: PCS | D38: Maintenance on AC side | E38: Unintended PCS restart back-feeds equipment under maintenance | F38: PCS automatic restart logic re-enables output on grid return or after alarm reset | G38: PCS starts while downstream transformer / MV cable is under maintenance and back-feeds it | H38: PCS energizes transformer / MV cable worker contact | I38: Energized equipment under work arc | J38: Worker on transformer/MV cable is electrocuted or exposed to arc flash. | K38: O&M technicians, contractors | L38: Electric shock | M38: Electric shock Arc flash | N38: Breaker/isolator position; LOTO status | O38: SF-22 | P38: =IF(O38="","none",IF(SUMPRODUCT(ISNUMBER(SEARCH('Safety functions'!$A$2:$A$200,O38))*('Safety functions'!$A$2:$A$200<>""))=LEN(O38)-LEN(SUBSTITUTE(O38,",",""))+1,"OK","check")) -> OK
A39: GR-03 | B39: Grid interface / AC side | C39: Grid / AC equipment | D39: Operation / switching | E39: Internal arc fault in MV switchgear | F39: Internal insulation failure (partial discharge, contamination, rodent) or maloperation (closing onto earth) | G39: Internal arc in switchgear | H39: Arc pressure rise, hot gas release, panel rupture | I39: Internal arc pressure wave hot gas switchgear fire | J39: Operator standing in front of switchgear during switching is exposed to arc blast and hot gases → burns, blast injury. | K39: Operators | L39: Arc flash | M39: Arc flash Fire | N39: Partial discharge; arc detection (light + current) | O39: SF-23 | P39: =IF(O39="","none",IF(SUMPRODUCT(ISNUMBER(SEARCH('Safety functions'!$A$2:$A$200,O39))*('Safety functions'!$A$2:$A$200<>""))=LEN(O39)-LEN(SUBSTITUTE(O39,",",""))+1,"OK","check")) -> OK
A40: GR-04 | B40: Grid interface / AC side | C40: Grid / AC equipment | D40: Normal operation | E40: Transformer internal fault | F40: Winding insulation failure (overload, harmonics from PCS, DC injection saturation, aging) | G40: Internal arc in oil → gas generation → tank pressure | H40: Arc in oil tank rupture oil spill fire fire exposure to BESS | I40: Transformer explosion oil pool fire fire spread to BESS (→ EX-01) | J40: Personnel near transformer exposed to blast, burning oil and radiant heat. | K40: O&M technicians, firefighters | L40: Fire | M40: Fire Explosion | N40: Buchholz / sudden pressure; winding & oil temperature; DGA | O40: SF-24 | P40: =IF(O40="","none",IF(SUMPRODUCT(ISNUMBER(SEARCH('Safety functions'!$A$2:$A$200,O40))*('Safety functions'!$A$2:$A$200<>""))=LEN(O40)-LEN(SUBSTITUTE(O40,",",""))+1,"OK","check")) -> OK
A41: GR-05 | B41: Grid interface / AC side | C41: Grid / AC equipment | D41: Grid fault | E41: AC fault not cleared by protection | F41: Short circuit on AC side with protection miscoordination or breaker failure to trip | G41: Sustained fault current through PCS output cables | H41: Sustained overcurrent cable/busbar overheating fire; arc | I41: Cable fire arc PCS damage | J41: Personnel near PCS/cable route exposed to fire and toxic smoke. | K41: O&M technicians, firefighters | L41: Fire | M41: Fire Arc flash Toxic | N41: Fault current; breaker status | O41: SF-25 | P41: =IF(O41="","none",IF(SUMPRODUCT(ISNUMBER(SEARCH('Safety functions'!$A$2:$A$200,O41))*('Safety functions'!$A$2:$A$200<>""))=LEN(O41)-LEN(SUBSTITUTE(O41,",",""))+1,"OK","check")) -> OK
A42: GR-06 | B42: Grid interface / AC side | C42: Grid / AC equipment | D42: Reconnection / auto-reclose | E42: Out-of-phase connection to grid | F42: Synchronization / sync-check failure or utility auto-reclose onto energized island | G42: Out-of-phase closure → very high transient current | H42: Transient overcurrent IGBT / capacitor rupture PCS explosion / fire | I42: PCS component rupture projectiles PCS fire | J42: Person near PCS cabinet exposed to projectiles, blast and fire. | K42: O&M technicians | L42: Explosion | M42: Explosion Fire | N42: Phase angle / voltage difference at breaker | O42: SF-20, SF-21 | P42: =IF(O42="","none",IF(SUMPRODUCT(ISNUMBER(SEARCH('Safety functions'!$A$2:$A$200,O42))*('Safety functions'!$A$2:$A$200<>""))=LEN(O42)-LEN(SUBSTITUTE(O42,",",""))+1,"OK","check")) -> OK
A43: GR-07 | B43: Grid interface / AC side | C43: PCS | D43: Normal operation | E43: PCS power-semiconductor failure | F43: IGBT failure (short) with desaturation protection failure | G43: Shoot-through discharges DC-link capacitors / battery into power stage | H43: Shoot-through capacitor/IGBT rupture arc PCS cabinet fire | I43: PCS explosion arc cabinet fire | J43: Technician near PCS exposed to blast, arc and fire. | K43: O&M technicians | L43: Fire | M43: Fire Explosion Arc flash | N43: Desat signal; DC-link current | O43: SF-06 | P43: =IF(O43="","none",IF(SUMPRODUCT(ISNUMBER(SEARCH('Safety functions'!$A$2:$A$200,O43))*('Safety functions'!$A$2:$A$200<>""))=LEN(O43)-LEN(SUBSTITUTE(O43,",",""))+1,"OK","check")) -> OK
A44: GR-08 | B44: Grid interface / AC side | C44: PCS | D44: Normal operation | E44: AC filter capacitor overstress | F44: Grid overvoltage or harmonic resonance | G44: Filter capacitors overheat | H44: Capacitor overheating rupture fire | I44: Capacitor rupture PCS fire | J44: Personnel near PCS exposed to fire/smoke. | K44: O&M technicians | L44: Fire | M44: Fire | N44: Harmonic distortion; capacitor temperature/current | O44: SF-26 | P44: =IF(O44="","none",IF(SUMPRODUCT(ISNUMBER(SEARCH('Safety functions'!$A$2:$A$200,O44))*('Safety functions'!$A$2:$A$200<>""))=LEN(O44)-LEN(SUBSTITUTE(O44,",",""))+1,"OK","check")) -> OK
A45: CS-01 | B45: Control / Software / Cyber | C45: BMS | D45: Commissioning / after update | E45: Incorrect BMS protection settings (systematic fault) | F45: Wrong BMS protection parameters (firmware update error, wrong cell-chemistry profile, commissioning error) | G45: BMS OV / OT / OC limits set beyond cell safe limits → BMS never requests stop or opens contactor | H45: Operation beyond safe window with no trip overcharge / overtemperature TR | I45: Cell thermal runaway (TR) → propagation to adjacent cells/modules flammable + toxic vent gas (H2, CO, HF, VOC) release module/rack fire possible deflagration in enclosure fire spread to adjacent containers/PCS | J45: Technician/firefighter at or near the container is exposed to fire, jet flame and radiant heat → burns. Person opening or standing at the enclosure door is exposed to deflagration overpressure, fireball and projectiles (door, panels). Personnel/public downwind inhale toxic combustion gases (HF, CO, HCN) → poisoning. | K45: O&M technicians, firefighters, public near site fence / downwind | L45: Fire | M45: Fire Explosion Toxic | N45: Parameter checksum / configuration audit | O45: SF-01, SF-10, SF-34 | P45: =IF(O45="","none",IF(SUMPRODUCT(ISNUMBER(SEARCH('Safety functions'!$A$2:$A$200,O45))*('Safety functions'!$A$2:$A$200<>""))=LEN(O45)-LEN(SUBSTITUTE(O45,",",""))+1,"OK","check")) -> OK
A46: CS-02 | B46: Control / Software / Cyber | C46: EMS / SCADA | D46: Any | E46: Cyber attack on BESS control systems | F46: Cyber intrusion into EMS/SCADA/BMS | G46: Malicious setpoints, disabled alarms/protections, falsified BMS data, HVAC shut off | H46: Forced overcharge / overcurrent / cooling loss while protections suppressed TR | I46: Cell thermal runaway (TR) → propagation to adjacent cells/modules flammable + toxic vent gas (H2, CO, HF, VOC) release module/rack fire possible deflagration in enclosure fire spread to adjacent containers/PCS | J46: Technician/firefighter at or near the container is exposed to fire, jet flame and radiant heat → burns. Person opening or standing at the enclosure door is exposed to deflagration overpressure, fireball and projectiles (door, panels). Personnel/public downwind inhale toxic combustion gases (HF, CO, HCN) → poisoning. | K46: O&M technicians, firefighters, public near site fence / downwind | L46: Fire | M46: Fire Explosion Toxic | N46: Unauthorized config change; abnormal commands | O46: SF-01, SF-10 | P46: =IF(O46="","none",IF(SUMPRODUCT(ISNUMBER(SEARCH('Safety functions'!$A$2:$A$200,O46))*('Safety functions'!$A$2:$A$200<>""))=LEN(O46)-LEN(SUBSTITUTE(O46,",",""))+1,"OK","check")) -> OK
... A51: AU-03 | B51: Auxiliary / Suppression systems | C51: Auxiliary & safety systems | D51: Normal operation | E51: Hydrogen generation from UPS batteries | F51: UPS charger overvoltage / battery thermal runaway (lead-acid) | G51: Excess H2 evolution in room with failed ventilation | H51: H2 accumulates ignition explosion | I51: H2 explosion fire in control room | J51: Person in control/aux room exposed to explosion and fire. | K51: Operators, O&M technicians | L51: Explosion | M51: Explosion Fire | N51: H2 concentration; float voltage | O51: SF-12, SF-30 | P51: =IF(O51="","none",IF(SUMPRODUCT(ISNUMBER(SEARCH('Safety functions'!$A$2:$A$200,O51))*('Safety functions'!$A$2:$A$200<>""))=LEN(O51)-LEN(SUBSTITUTE(O51,",",""))+1,"OK","check")) -> OK
...

Sheet Safety functions
A1: SF ID | B1: Safety function | C1: Type | D1: Sensor (S) | E1: Measured variable | F1: Logic solver (L) | G1: Final element (A) | H1: Final element tags (; separated) | I1: Safe state | J1: Demand mode | K1: Must not share (independence) | L1: Reference | M1: Check: scenarios citing this SF
A2: SF-01 | B2: Cell overvoltage trip | C2: SIF candidate | D2: Independent cell-voltage monitor (secondary AFE / hardware OV comparator per cell) | E2: Cell voltage (each cell) | F2: Independent protection board or safety PLC / safety relay (not the main BMS CPU) | G2: Rack DC contactor (de-energize to open) + PCS DC breaker shunt trip | H2: DC contactor; DC breaker | I2: Charging stopped, battery isolated from PCS | J2: Low demand → PFDavg | K2: Must NOT share voltage sensor, CPU, software or power with BMS charge control (see independence section of attachment). Hard-coded threshold, not configurable via EMS. | L2: IEC 61508 / 61511, IEC 62619, IEC 62933-5-2 | M2: =COUNTIF(Scenarios!$O$2:$O$500,"*"&A2&"*") -> 9
A3: SF-02 | B3: Communication-loss / watchdog → PCS to zero power | C3: Control-level protection (usually not credited as IPL) | D3: Heartbeat / data-freshness counter on BMS–PCS link | E3: Message age, counter increment | F3: PCS controller watchdog function | G3: PCS gate-blocking (power stage off) / PCS AC contactor | H3: PCS power stage / AC contactor | I3: PCS output = 0 kW | J3: Low demand | K3: Resides in the same PCS controller that may cause OV-01 → cannot be IPL for OV-01; OK as IPL for OV-02 only if PCS is independent of the failed link. | L3: IEC 62933-5-2 | M3: =COUNTIF(Scenarios!$O$2:$O$500,"*"&A3&"*") -> 2
A4: SF-03 | B4: External BMS watchdog → safe state | C4: SIF candidate / fail-safe design | D4: Watchdog pulse from BMS processor | E4: Pulse present / missing | F4: External hardware watchdog IC / timer relay | G4: Rack DC contactor coil drop-out | H4: DC contactor | I4: Contactors open | J4: Low demand | K4: Watchdog must be external to the monitored processor and have its own power. | L4: IEC 61508-2/-3 | M4: =COUNTIF(Scenarios!$O$2:$O$500,"*"&A4&"*") -> 1
A5: SF-04 | B5: Cell undervoltage trip + charge-inhibit lockout | C5: SIF candidate | D5: Cell-voltage monitor | E5: Cell voltage (min) | F5: BMS or independent protection board | G5: Rack DC contactor + latched 'charge inhibit' flag to PCS | H5: DC contactor; Start/close/charge inhibit | I5: Discharge stopped; recharge blocked until inspection | J5: Low demand | K5: Lockout must survive power cycling (non-volatile). Independent of SOC algorithm. | L5: IEC 62619 | M5: =COUNTIF(Scenarios!$O$2:$O$500,"*"&A5&"*") -> 2
A6: SF-05 | B6: Low-temperature charge inhibit | C6: SIF candidate | D6: Cell temperature sensors (NTC) | E6: Cell temperature | F6: BMS / protection board | G6: PCS charge-current limit = 0 and/or DC contactor | H6: PCS power stage / AC contactor; DC contactor | I6: No charging below T_min | J6: Low demand | K6: Should not rely on the same NTC used for heater control. | L6: IEC 62619 | M6: =COUNTIF(Scenarios!$O$2:$O$500,"*"&A6&"*") -> 1
A7: SF-06 | B7: Overcurrent trip (DC) | C7: SIF candidate / self-acting protection | D7: Rack current sensor (shunt / Hall) independent of PCS current sensor – or fuse element (sensor+logic+actuator in one) | E7: DC current | F7: Independent protection board / DC breaker trip unit (fuse = no logic solver) | G7: DC breaker / rack fuse / contactor | H7: DC breaker; Fuse; DC contactor | I7: Current interrupted | J7: Low demand (check – if trips often, fix design) | K7: Do not use PCS current sensor (shared with IE OC-01). Contactors must be rated to break fault current, otherwise fuse/breaker must do it. | L7: IEC 60947-2, IEC 60269 | M7: =COUNTIF(Scenarios!$O$2:$O$500,"*"&A7&"*") -> 4
A8: SF-07 | B8: DC arc-fault detection and interruption | C8: SIF candidate | D8: Arc-fault detector (HF current signature) | E8: Arc signature on DC conductors | F8: AFD relay | G8: DC breaker shunt trip | H8: DC breaker | I8: Arc extinguished, circuit open | J8: Low demand | K8: Nuisance-trip vs detection trade-off; test regularly. | L8: UL 1699B (PV analogue), IEC 63027 | M8: =COUNTIF(Scenarios!$O$2:$O$500,"*"&A8&"*") -> 2
A9: SF-08 | B9: Contactor weld detection | C9: Diagnostic + trip | D9: Contactor auxiliary contact + voltage across main contacts | E9: Commanded vs actual contact state | F9: BMS / protection board | G9: Upstream DC breaker shunt trip + 'not isolated' indication | H9: DC breaker; Indication / alarm | I9: Circuit isolated by second device; HMI shows 'still energized' | J9: Low demand | K9: Upstream breaker must be a different device type (diversity) from the welded contactor. | L9: IEC 60947-4-1 | M9: =COUNTIF(Scenarios!$O$2:$O$500,"*"&A9&"*") -> 1
A10: SF-09 | B10: Hot-joint / connection monitoring | C10: Detection → derate/trip | D10: Busbar/terminal temperature sensors or ΔV across joints | E10: Joint temperature / voltage drop | F10: BMS | G10: PCS derate command → DC contactor if high-high | H10: PCS power stage / AC contactor; DC contactor | I10: Reduced current or isolation | J10: Low demand | K10: Derate part is normal control; only high-high trip is a safety function. | L10: — | M10: =COUNTIF(Scenarios!$O$2:$O$500,"*"&A10&"*") -> 1
A11: SF-10 | B11: Cell overtemperature trip | C11: SIF candidate | D11: Redundant / diverse cell temperature sensors (NTC + independent thermal sensor) | E11: Cell / module temperature | F11: Independent protection board or safety PLC | G11: PCS stop + rack DC contactor open | H11: PCS power stage / AC contactor; DC contactor | I11: No current; heat generation stopped | J11: Low demand → PFDavg | K11: Sensor independent from HVAC control sensor and from BMS derating loop. | L11: IEC 62619, IEC 62933-5-2 | M11: =COUNTIF(Scenarios!$O$2:$O$500,"*"&A11&"*") -> 5
A12: SF-11 | B12: Off-gas detection → isolate | C12: SIF candidate (early warning) | D12: H2 / CO / VOC (electrolyte vapour) detectors in module or enclosure | E12: Gas concentration | F12: Gas-detection controller or safety PLC | G12: Rack DC contactors + PCS trip + alarm | H12: DC contactor; PCS power stage / AC contactor; Indication / alarm | I12: Battery isolated before TR develops | J12: Low demand | K12: Detects TR regardless of cause → good diverse layer. Controller on UPS. | L12: UL 9540A, NFPA 855 | M12: =COUNTIF(Scenarios!$O$2:$O$500,"*"&A12&"*") -> 10
A13: SF-12 | B13: Explosion-prevention exhaust ventilation | C13: SIF candidate (mitigation) | D13: Flammable gas detectors (H2 / %LFL) | E13: Gas concentration (%LFL) | F13: Gas panel / safety PLC (UPS-backed) | G13: Exhaust fan(s) + inlet louvres/dampers open | H13: Ventilation fan / damper | I13: Gas kept below 25 % LFL | J13: Low demand | K13: Fans, detectors and controller must stay powered when main aux fails (AU-01). Fan failure alarm. | L13: NFPA 69, NFPA 855 | M13: =COUNTIF(Scenarios!$O$2:$O$500,"*"&A13&"*") -> 4
... A35: SF-34 | B35: Parameter integrity check at start-up | C35: Software diagnostic | D35: Configuration checksum / signed firmware | E35: Parameter set vs approved baseline | F35: BMS / PCS bootloader | G35: Start inhibit | H35: Start/close/charge inhibit | I35: System does not run with unapproved limits | J35: On-demand at start | K35: Systematic-fault measure; complements (does not replace) hard-coded SF-01/SF-10. | L35: IEC 61508-3, IEC 62443 | M35: =COUNTIF(Scenarios!$O$2:$O$500,"*"&A35&"*") -> 2

Sheet Other measures
A1: Measure | B1: Scenarios (comma-separated)
A2: Passive – propagation barriers / cell spacing | B2: IC-01, all TR
A3: Passive – bollards / crash barriers | B3: ME-01
A4: Passive – separation distance / fire-rated walls | B4: EX-01, GR-04
A5: Passive – deflagration vents / explosion panels | B5: GX-01
A6: Passive – lightning protection system + SPD | B6: EX-03
A7: Passive – ingress protection (IP rating, sealing) | B7: EX-04, EX-05
A8: Passive – IAC-rated switchgear, pressure relief | B8: GR-03
A9: Design – module service disconnect / plug | B9: SH-02
A10: Design – hardwired (non-networked) safety trips; network zoning | B10: CS-02
A11: Admin – de-energized work policy, LOTO, PPE | B11: SH-02, SH-04, GR-02
A12: Admin – lifting plan | B12: ME-03
... A18: Admin – management of change for parameters/firmware | B18: CS-01

Sheet Lists
A1: Component | B1: Colour (hex) | C1: PCS/BMS panel text (leave empty = not in panel) | E1: Group (display order) | G1: Hazard type | H1: Icon | I1: Show as filter (Y/N) | K1: SF type filter chips (keyword in 'Type')
A2: PCS | B2: #5aa9ff | C2: Power conversion: follows setpoints, converts DC↔AC. | E2: Overcharge / Overvoltage | G2: Fire | H2: 🔥 | I2: Y | K2: SIF candidate
A3: BMS | B3: #a78bfa | C3: Battery management: measures cells, computes limits, commands stop. | E3: Overdischarge / Low-temperature charging | G3: Explosion | H3: 💥 | I3: Y | K3: Protection
A4: BMS–PCS comm link | B4: #2dd4bf | C4: The link that carries BMS limits to the PCS. | E4: Overcurrent / Short circuit | G4: Toxic | H4: ☠️ | I4: Y | K4: Interlock
A5: Battery cell | B5: #fbbf24 | E5: Internal cell defect | G5: Electric shock | H5: ⚡ | I5: Y | K5: Detection
A6: DC electrical | B6: #fb923c | E6: Thermal management / Overtemperature | G6: Arc flash | H6: ✴️ | I6: Y | K6: Fail-safe
A7: Thermal management (HVAC) | B7: #67e8f9 | E7: Mechanical / External damage | G7: Asphyxiation | H7: 🫁 | I7: Y | K7: Manual
A8: Grid / AC equipment | B8: #60a5fa | E8: External fire / Environment | G8: Mechanical | H8: ⚙️ | I8: Y | K8: Diagnostic
A9: EMS / SCADA | B9: #f472b6 | E9: Gas release / Explosion / Toxic | G9: Chemical burn | H9: 🧪 | I9: N | K9: Control-level
A10: Auxiliary & safety systems | B10: #4ade80 | E10: Electric shock / Arc flash (DC)
A11: External / site | B11: #a3a3a3 | E11: Grid interface / AC side
A12: People & lifecycle | B12: #fda4af | E12: Control / Software / Cyber
E13: Auxiliary / Suppression systems
E14: Lifecycle (transport → decommissioning)
E15: Emergency response / Post-fire

Sheet Page text
A1: Key (do not change) | B1: Text
A2: title | B2: Hazardous scenarios in a grid-connected BESS
A3: subtitle | B3: Each scenario is written as in step 1 of the LOPA: one initiating event, the sequence it starts, what physically happens, and how a person gets hurt. Every initiating event belongs to one component only, so PCS and BMS failures are separate scenarios.
A4: owners_heading | B4: PCS, BMS and the link between them
A5: owners_intro | B5: Your example says "PCS / BMS charging control fails". These are different failures with different independence problems, so they are split. If the PCS is the cause, a BMS-based trip can be credited; if the BMS is the cause, only a trip that does not use the BMS sensor, CPU or software can be credited.
A6: reuse_warning | B6: The rack DC contactor carries most of the load. A welded contactor (scenario [OC-03]) defeats every function that relies on it. A diverse second final element, such as a DC breaker with shunt trip, gives a 1oo2 path to the safe state.
A7: home_url | B7: Main_IEC61508_Safety_Lifecycle_Overview.html
A8: home_label | B8: Home · IEC 61508 Safety Lifecycle
A10: home_url: file name of the home page. Same folder = just the file name; other folder = relative path with / and ../ (e.g. ../Main_IEC61508_Safety_Lifecycle_Overview.html).

Sheet Checks
A1: Check | B1: Value
A2: Scenarios | B2: =COUNTA(Scenarios!A2:A500) -> 56
A3: Safety functions | B3: =COUNTA('Safety functions'!A2:A200) -> 34
A4: Scenarios with no SF (passive/admin only) | B4: =COUNTIF(Scenarios!O2:O500,"")-(ROWS(Scenarios!O2:O500)-COUNTA(Scenarios!A2:A500)) -> 7
A5: Scenarios with unknown SF ID | B5: =COUNTIF(Scenarios!P2:P500,"check") -> 0
A6: Safety functions not cited by any scenario | B6: =COUNTIF('Safety functions'!M2:M200,0) -> 0
A7: Scenarios with component not in Lists | B7: =SUMPRODUCT((Scenarios!A2:A500<>"")*(COUNTIF(Lists!A2:A60,Scenarios!C2:C500)=0)) -> 0
A8: Scenarios with group not in Lists | B8: =SUMPRODUCT((Scenarios!A2:A500<>"")*(COUNTIF(Lists!E2:E60,Scenarios!B2:B500)=0)) -> 0
A10: Expected: last four checks = 0 before rebuilding the HTML.
